Workbook

Sheet Summary
A1: FORGE AI: delivery summary
A2: Everything on this page is worked out from the Features sheet. Nothing here needs typing.
A4: Overall % done | B4: =AVERAGE(Features!$R$5:$R$120)
A5: Features in total | B5: =COUNTIF(Features!$C$5:$C$120,"<>")
A6: Must-have features done | B6: =COUNTIFS(Features!$L$5:$L$120,"Yes",Features!$Q$5:$Q$120,"Done")&" of "&COUNTIF(Features!$L$5:$L$120,"Yes")
A7: Features stuck right now | B7: =COUNTIF(Features!$Q$5:$Q$120,"Stuck")
A10: Features by status
A11: Status | B11: Features | C11: Share
A12: Not started | B12: =COUNTIF(Features!$Q$5:$Q$120,A12) | C12: =IFERROR(B12/$B$5,0)
A13: In progress | B13: =COUNTIF(Features!$Q$5:$Q$120,A13) | C13: =IFERROR(B13/$B$5,0)
A14: Being checked | B14: =COUNTIF(Features!$Q$5:$Q$120,A14) | C14: =IFERROR(B14/$B$5,0)
A15: Done | B15: =COUNTIF(Features!$Q$5:$Q$120,A15) | C15: =IFERROR(B15/$B$5,0)
A16: Stuck | B16: =COUNTIF(Features!$Q$5:$Q$120,A16) | C16: =IFERROR(B16/$B$5,0)
A18: Progress by phase
A19: Phase | B19: Features | C19: Done | D19: % done
A20: Phase 1: Accounts and job matching | B20: =COUNTIF(Features!$G$5:$G$120,A20) | C20: =COUNTIFS(Features!$G$5:$G$120,A20,Features!$Q$5:$Q$120,"Done") | D20: =IFERROR(AVERAGEIF(Features!$G$5:$G$120,A20,Features!$R$5:$R$120),0)
A21: Phase 2: Resumes, learning and own voice | B21: =COUNTIF(Features!$G$5:$G$120,A21) | C21: =COUNTIFS(Features!$G$5:$G$120,A21,Features!$Q$5:$Q$120,"Done") | D21: =IFERROR(AVERAGEIF(Features!$G$5:$G$120,A21,Features!$R$5:$R$120),0)
A22: Phase 3: Interview practice and LinkedIn | B22: =COUNTIF(Features!$G$5:$G$120,A22) | C22: =COUNTIFS(Features!$G$5:$G$120,A22,Features!$Q$5:$Q$120,"Done") | D22: =IFERROR(AVERAGEIF(Features!$G$5:$G$120,A22,Features!$R$5:$R$120),0)
A23: Phase 4: Progress tracking and organisations | B23: =COUNTIF(Features!$G$5:$G$120,A23) | C23: =COUNTIFS(Features!$G$5:$G$120,A23,Features!$Q$5:$Q$120,"Done") | D23: =IFERROR(AVERAGEIF(Features!$G$5:$G$120,A23,Features!$R$5:$R$120),0)
A24: Phase 5: Launch checks | B24: =COUNTIF(Features!$G$5:$G$120,A24) | C24: =COUNTIFS(Features!$G$5:$G$120,A24,Features!$Q$5:$Q$120,"Done") | D24: =IFERROR(AVERAGEIF(Features!$G$5:$G$120,A24,Features!$R$5:$R$120),0)
A26: Progress by area
A27: Area | B27: Features | C27: Done | D27: % done
A28: Accounts and setup | B28: =COUNTIF(Features!$B$5:$B$120,A28) | C28: =COUNTIFS(Features!$B$5:$B$120,A28,Features!$Q$5:$Q$120,"Done") | D28: =IFERROR(AVERAGEIF(Features!$B$5:$B$120,A28,Features!$R$5:$R$120),0)
A29: Finding jobs | B29: =COUNTIF(Features!$B$5:$B$120,A29) | C29: =COUNTIFS(Features!$B$5:$B$120,A29,Features!$Q$5:$Q$120,"Done") | D29: =IFERROR(AVERAGEIF(Features!$B$5:$B$120,A29,Features!$R$5:$R$120),0)
A30: Resumes and learning | B30: =COUNTIF(Features!$B$5:$B$120,A30) | C30: =COUNTIFS(Features!$B$5:$B$120,A30,Features!$Q$5:$Q$120,"Done") | D30: =IFERROR(AVERAGEIF(Features!$B$5:$B$120,A30,Features!$R$5:$R$120),0)
A31: Writing in your own voice | B31: =COUNTIF(Features!$B$5:$B$120,A31) | C31: =COUNTIFS(Features!$B$5:$B$120,A31,Features!$Q$5:$Q$120,"Done") | D31: =IFERROR(AVERAGEIF(Features!$B$5:$B$120,A31,Features!$R$5:$R$120),0)
A32: Interview practice | B32: =COUNTIF(Features!$B$5:$B$120,A32) | C32: =COUNTIFS(Features!$B$5:$B$120,A32,Features!$Q$5:$Q$120,"Done") | D32: =IFERROR(AVERAGEIF(Features!$B$5:$B$120,A32,Features!$R$5:$R$120),0)
A33: LinkedIn and outreach | B33: =COUNTIF(Features!$B$5:$B$120,A33) | C33: =COUNTIFS(Features!$B$5:$B$120,A33,Features!$Q$5:$Q$120,"Done") | D33: =IFERROR(AVERAGEIF(Features!$B$5:$B$120,A33,Features!$R$5:$R$120),0)
A34: Progress tracking | B34: =COUNTIF(Features!$B$5:$B$120,A34) | C34: =COUNTIFS(Features!$B$5:$B$120,A34,Features!$Q$5:$Q$120,"Done") | D34: =IFERROR(AVERAGEIF(Features!$B$5:$B$120,A34,Features!$R$5:$R$120),0)
A35: For organisations | B35: =COUNTIF(Features!$B$5:$B$120,A35) | C35: =COUNTIFS(Features!$B$5:$B$120,A35,Features!$Q$5:$Q$120,"Done") | D35: =IFERROR(AVERAGEIF(Features!$B$5:$B$120,A35,Features!$R$5:$R$120),0)
A36: Launch checks | B36: =COUNTIF(Features!$B$5:$B$120,A36) | C36: =COUNTIFS(Features!$B$5:$B$120,A36,Features!$Q$5:$Q$120,"Done") | D36: =IFERROR(AVERAGEIF(Features!$B$5:$B$120,A36,Features!$R$5:$R$120),0)
A38: Work per developer (screen and backend jobs counted separately)
A39: Developer | B39: Jobs | C39: Done | D39: Under way | E39: Stuck | F39: % done
A40: Developer A | B40: =COUNTIF(Features!$J$5:$J$120,A40)+COUNTIF(Features!$K$5:$K$120,A40) | C40: =COUNTIFS(Features!$J$5:$J$120,A40,Features!$O$5:$O$120,"Done")+COUNTIFS(Features!$K$5:$K$120,A40,Features!$P$5:$P$120,"Done") | D40: =COUNTIFS(Features!$J$5:$J$120,A40,Features!$O$5:$O$120,"In progress")+COUNTIFS(Features!$K$5:$K$120,A40,Features!$P$5:$P$120,"In progress")+COUNTIFS(Features!$J$5:$J$120,A40,Features!$O$5:$O$120,"Being checked")+COUNTIFS(Features!$K$5:$K$120,A40,Features!$P$5:$P$120,"Being checked") | E40: =COUNTIFS(Features!$J$5:$J$120,A40,Features!$O$5:$O$120,"Stuck")+COUNTIFS(Features!$K$5:$K$120,A40,Features!$P$5:$P$120,"Stuck") | F40: =IFERROR(C40/B40,0)
A41: Developer B | B41: =COUNTIF(Features!$J$5:$J$120,A41)+COUNTIF(Features!$K$5:$K$120,A41) | C41: =COUNTIFS(Features!$J$5:$J$120,A41,Features!$O$5:$O$120,"Done")+COUNTIFS(Features!$K$5:$K$120,A41,Features!$P$5:$P$120,"Done") | D41: =COUNTIFS(Features!$J$5:$J$120,A41,Features!$O$5:$O$120,"In progress")+COUNTIFS(Features!$K$5:$K$120,A41,Features!$P$5:$P$120,"In progress")+COUNTIFS(Features!$J$5:$J$120,A41,Features!$O$5:$O$120,"Being checked")+COUNTIFS(Features!$K$5:$K$120,A41,Features!$P$5:$P$120,"Being checked") | E41: =COUNTIFS(Features!$J$5:$J$120,A41,Features!$O$5:$O$120,"Stuck")+COUNTIFS(Features!$K$5:$K$120,A41,Features!$P$5:$P$120,"Stuck") | F41: =IFERROR(C41/B41,0)
A43: Screens vs backend
A44: Side | B44: Jobs | C44: Done | D44: Stuck | E44: % done
A45: Screen work (frontend) | B45: =COUNTIF(Features!$O$5:$O$120,"<>")-COUNTIF(Features!$O$5:$O$120,"Not needed") | C45: =COUNTIF(Features!$O$5:$O$120,"Done") | D45: =COUNTIF(Features!$O$5:$O$120,"Stuck") | E45: =IFERROR(C45/B45,0)
A46: Backend work | B46: =COUNTIF(Features!$P$5:$P$120,"<>")-COUNTIF(Features!$P$5:$P$120,"Not needed") | C46: =COUNTIF(Features!$P$5:$P$120,"Done") | D46: =COUNTIF(Features!$P$5:$P$120,"Stuck") | E46: =IFERROR(C46/B46,0)
A48: Checkpoints
...

Sheet Features
A1: Feature list: every feature in the FORGE AI Product Vision
A2: One row per feature. Read 'What it does' first. Update only the yellow columns; the grey status and % columns work themselves out.
A4: No. | B4: Area | C4: Feature | D4: What it does (for the user) | E4: Screen work to do (frontend) | F4: Backend work to do | G4: Phase | H4: Week | I4: Due | J4: Screen built by | K4: Backend built by | L4: Must have? | M4: What we have today | N4: Waiting on | O4: Screen status | P4: Backend status | Q4: Overall | R4: % done | S4: Notes / next step
A5: 1 | B5: Accounts and setup | C5: Sign up and log in | D5: People create an account (job seeker, company, university, training institute or staffing firm) and log in safely. | E5: Sign-up and login pages, choose account type, clear error messages | F5: Store passwords securely, keep people logged in, password reset | G5: Phase 1: Accounts and job matching | H5: 1 | I5: =Settings!$B$5+(H5-1)*7+4 | J5: Developer B | K5: Developer B | L5: Yes | M5: Works, but saves to local files with weak password protection | N5: Where the app will be hosted | O5: Not started | P5: Not started | Q5: =IF(AND(O5="Not needed",P5="Not needed"),"Not needed",IF(OR(O5="Stuck",P5="Stuck"),"Stuck",IF(AND(OR(O5="Done",O5="Not needed"),OR(P5="Done",P5="Not needed")),"Done",IF(AND(OR(O5="Not started",O5="Not needed"),OR(P5="Not started",P5="Not needed")),"Not started",IF(AND(OR(O5="Being checked",O5="Done",O5="Not needed"),OR(P5="Being checked",P5="Done",P5="Not needed")),"Being checked","In progress"))))) | R5: =IFERROR((IF(OR(O5="Not needed",O5="Stuck"),0,INDEX(Settings!$E$5:$E$8,MATCH(O5,Settings!$D$5:$D$8,0)))+IF(OR(P5="Not needed",P5="Stuck"),0,INDEX(Settings!$E$5:$E$8,MATCH(P5,Settings!$D$5:$D$8,0))))/((O5<>"Not needed")+(P5<>"Not needed")),0)
A6: 2 | B6: Accounts and setup | C6: Save everything in a proper database | D6: Everything a user does is saved reliably and is there next time they log in. | E6: Pages read and save through the new database | F6: Set up the database, move existing accounts across | G6: Phase 1: Accounts and job matching | H6: 1 | I6: =Settings!$B$5+(H6-1)*7+4 | J6: Developer B | K6: Developer B | L6: Yes | M6: Data saved in local files | N6: Which database to use | O6: Not started | P6: Not started | Q6: =IF(AND(O6="Not needed",P6="Not needed"),"Not needed",IF(OR(O6="Stuck",P6="Stuck"),"Stuck",IF(AND(OR(O6="Done",O6="Not needed"),OR(P6="Done",P6="Not needed")),"Done",IF(AND(OR(O6="Not started",O6="Not needed"),OR(P6="Not started",P6="Not needed")),"Not started",IF(AND(OR(O6="Being checked",O6="Done",O6="Not needed"),OR(P6="Being checked",P6="Done",P6="Not needed")),"Being checked","In progress"))))) | R6: =IFERROR((IF(OR(O6="Not needed",O6="Stuck"),0,INDEX(Settings!$E$5:$E$8,MATCH(O6,Settings!$D$5:$D$8,0)))+IF(OR(P6="Not needed",P6="Stuck"),0,INDEX(Settings!$E$5:$E$8,MATCH(P6,Settings!$D$5:$D$8,0))))/((O6<>"Not needed")+(P6<>"Not needed")),0)
A7: 3 | B7: Accounts and setup | C7: Ask permission before using personal data | D7: Users agree to how their data is used before anything is collected. | E7: Permission screen at sign-up, privacy settings page | F7: Record each user's permissions | G7: Phase 1: Accounts and job matching | H7: 1 | I7: =Settings!$B$5+(H7-1)*7+4 | J7: Developer B | K7: Developer B | L7: Yes | M7: Nothing built yet | N7: Permission wording from client | O7: Not started | P7: Not started | Q7: =IF(AND(O7="Not needed",P7="Not needed"),"Not needed",IF(OR(O7="Stuck",P7="Stuck"),"Stuck",IF(AND(OR(O7="Done",O7="Not needed"),OR(P7="Done",P7="Not needed")),"Done",IF(AND(OR(O7="Not started",O7="Not needed"),OR(P7="Not started",P7="Not needed")),"Not started",IF(AND(OR(O7="Being checked",O7="Done",O7="Not needed"),OR(P7="Being checked",P7="Done",P7="Not needed")),"Being checked","In progress"))))) | R7: =IFERROR((IF(OR(O7="Not needed",O7="Stuck"),0,INDEX(Settings!$E$5:$E$8,MATCH(O7,Settings!$D$5:$D$8,0)))+IF(OR(P7="Not needed",P7="Stuck"),0,INDEX(Settings!$E$5:$E$8,MATCH(P7,Settings!$D$5:$D$8,0))))/((O7<>"Not needed")+(P7<>"Not needed")),0)
A8: 4 | B8: Accounts and setup | C8: Put the app online with backups | D8: The app is reachable on a real web address and data is backed up every day. | E8: — | F8: Deploy to a server, daily backups, alerts if the site goes down | G8: Phase 1: Accounts and job matching | H8: 1 | I8: =Settings!$B$5+(H8-1)*7+4 | J8: — | K8: Developer B | L8: Yes | M8: Runs only on a developer's computer | N8: Hosting account | O8: Not needed | P8: Not started | Q8: =IF(AND(O8="Not needed",P8="Not needed"),"Not needed",IF(OR(O8="Stuck",P8="Stuck"),"Stuck",IF(AND(OR(O8="Done",O8="Not needed"),OR(P8="Done",P8="Not needed")),"Done",IF(AND(OR(O8="Not started",O8="Not needed"),OR(P8="Not started",P8="Not needed")),"Not started",IF(AND(OR(O8="Being checked",O8="Done",O8="Not needed"),OR(P8="Being checked",P8="Done",P8="Not needed")),"Being checked","In progress"))))) | R8: =IFERROR((IF(OR(O8="Not needed",O8="Stuck"),0,INDEX(Settings!$E$5:$E$8,MATCH(O8,Settings!$D$5:$D$8,0)))+IF(OR(P8="Not needed",P8="Stuck"),0,INDEX(Settings!$E$5:$E$8,MATCH(P8,Settings!$D$5:$D$8,0))))/((O8<>"Not needed")+(P8<>"Not needed")),0)
A9: 5 | B9: Accounts and setup | C9: Fill in your profile | D9: Users enter their role, target role, skills, experience, certifications and LinkedIn link. | E9: Profile form | F9: Save and load the profile | G9: Phase 1: Accounts and job matching | H9: 2 | I9: =Settings!$B$5+(H9-1)*7+4 | J9: Developer B | K9: Developer B | L9: Yes | M9: Form exists, saved to local files | N9: — | O9: Not started | P9: Not started | Q9: =IF(AND(O9="Not needed",P9="Not needed"),"Not needed",IF(OR(O9="Stuck",P9="Stuck"),"Stuck",IF(AND(OR(O9="Done",O9="Not needed"),OR(P9="Done",P9="Not needed")),"Done",IF(AND(OR(O9="Not started",O9="Not needed"),OR(P9="Not started",P9="Not needed")),"Not started",IF(AND(OR(O9="Being checked",O9="Done",O9="Not needed"),OR(P9="Being checked",P9="Done",P9="Not needed")),"Being checked","In progress"))))) | R9: =IFERROR((IF(OR(O9="Not needed",O9="Stuck"),0,INDEX(Settings!$E$5:$E$8,MATCH(O9,Settings!$D$5:$D$8,0)))+IF(OR(P9="Not needed",P9="Stuck"),0,INDEX(Settings!$E$5:$E$8,MATCH(P9,Settings!$D$5:$D$8,0))))/((O9<>"Not needed")+(P9<>"Not needed")),0)
A10: 6 | B10: Accounts and setup | C10: Upload your resume and photo | D10: Uploading a resume fills in the profile automatically. | E10: Upload button, page to check the filled-in details | F10: Read the resume file and pull out skills, years and job titles | G10: Phase 1: Accounts and job matching | H10: 2 | I10: =Settings!$B$5+(H10-1)*7+4 | J10: Developer B | K10: Developer A | L10: Yes | M10: Resume reader exists in the recruiter tool | N10: Sample resumes to test with | O10: Not started | P10: Not started | Q10: =IF(AND(O10="Not needed",P10="Not needed"),"Not needed",IF(OR(O10="Stuck",P10="Stuck"),"Stuck",IF(AND(OR(O10="Done",O10="Not needed"),OR(P10="Done",P10="Not needed")),"Done",IF(AND(OR(O10="Not started",O10="Not needed"),OR(P10="Not started",P10="Not needed")),"Not started",IF(AND(OR(O10="Being checked",O10="Done",O10="Not needed"),OR(P10="Being checked",P10="Done",P10="Not needed")),"Being checked","In progress"))))) | R10: =IFERROR((IF(OR(O10="Not needed",O10="Stuck"),0,INDEX(Settings!$E$5:$E$8,MATCH(O10,Settings!$D$5:$D$8,0)))+IF(OR(P10="Not needed",P10="Stuck"),0,INDEX(Settings!$E$5:$E$8,MATCH(P10,Settings!$D$5:$D$8,0))))/((O10<>"Not needed")+(P10<>"Not needed")),0)
A11: 7 | B11: Accounts and setup | C11: Welcome and first steps | D11: New users are guided through their first steps. | E11: Welcome page and checklist | F11: Remember which steps each user has done | G11: Phase 1: Accounts and job matching | H11: 3 | I11: =Settings!$B$5+(H11-1)*7+4 | J11: Developer B | K11: Developer B | L11: No | M11: Page exists but shows made-up sample data | N11: — | O11: Not started | P11: Not started | Q11: =IF(AND(O11="Not needed",P11="Not needed"),"Not needed",IF(OR(O11="Stuck",P11="Stuck"),"Stuck",IF(AND(OR(O11="Done",O11="Not needed"),OR(P11="Done",P11="Not needed")),"Done",IF(AND(OR(O11="Not started",O11="Not needed"),OR(P11="Not started",P11="Not needed")),"Not started",IF(AND(OR(O11="Being checked",O11="Done",O11="Not needed"),OR(P11="Being checked",P11="Done",P11="Not needed")),"Being checked","In progress"))))) | R11: =IFERROR((IF(OR(O11="Not needed",O11="Stuck"),0,INDEX(Settings!$E$5:$E$8,MATCH(O11,Settings!$D$5:$D$8,0)))+IF(OR(P11="Not needed",P11="Stuck"),0,INDEX(Settings!$E$5:$E$8,MATCH(P11,Settings!$D$5:$D$8,0))))/((O11<>"Not needed")+(P11<>"Not needed")),0)
A12: 8 | B12: Accounts and setup | C12: Home dashboard | D12: Users see their jobs, applications, interviews, profile views and streak at a glance. | E12: Connect the new dashboard design to real numbers | F12: Supply the dashboard numbers | G12: Phase 1: Accounts and job matching | H12: 3 | I12: =Settings!$B$5+(H12-1)*7+4 | J12: Developer B | K12: Developer A | L12: Yes | M12: New design done, numbers are made up | N12: — | O12: In progress | P12: Not started | Q12: =IF(AND(O12="Not needed",P12="Not needed"),"Not needed",IF(OR(O12="Stuck",P12="Stuck"),"Stuck",IF(AND(OR(O12="Done",O12="Not needed"),OR(P12="Done",P12="Not needed")),"Done",IF(AND(OR(O12="Not started",O12="Not needed"),OR(P12="Not started",P12="Not needed")),"Not started",IF(AND(OR(O12="Being checked",O12="Done",O12="Not needed"),OR(P12="Being checked",P12="Done",P12="Not needed")),"Being checked","In progress"))))) | R12: =IFERROR((IF(OR(O12="Not needed",O12="Stuck"),0,INDEX(Settings!$E$5:$E$8,MATCH(O12,Settings!$D$5:$D$8,0)))+IF(OR(P12="Not needed",P12="Stuck"),0,INDEX(Settings!$E$5:$E$8,MATCH(P12,Settings!$D$5:$D$8,0))))/((O12<>"Not needed")+(P12<>"Not needed")),0)
A13: 9 | B13: Finding jobs | C13: Collect jobs from company websites | D13: Real jobs are gathered from company career pages. | E13: Show where each job came from | F13: Collect jobs from career pages on a schedule | G13: Phase 1: Accounts and job matching | H13: 2 | I13: =Settings!$B$5+(H13-1)*7+4 | J13: Developer B | K13: Developer A | L13: Yes | M13: Jobs are made up in code | N13: List of target companies | O13: Not started | P13: Not started | Q13: =IF(AND(O13="Not needed",P13="Not needed"),"Not needed",IF(OR(O13="Stuck",P13="Stuck"),"Stuck",IF(AND(OR(O13="Done",O13="Not needed"),OR(P13="Done",P13="Not needed")),"Done",IF(AND(OR(O13="Not started",O13="Not needed"),OR(P13="Not started",P13="Not needed")),"Not started",IF(AND(OR(O13="Being checked",O13="Done",O13="Not needed"),OR(P13="Being checked",P13="Done",P13="Not needed")),"Being checked","In progress"))))) | R13: =IFERROR((IF(OR(O13="Not needed",O13="Stuck"),0,INDEX(Settings!$E$5:$E$8,MATCH(O13,Settings!$D$5:$D$8,0)))+IF(OR(P13="Not needed",P13="Stuck"),0,INDEX(Settings!$E$5:$E$8,MATCH(P13,Settings!$D$5:$D$8,0))))/((O13<>"Not needed")+(P13<>"Not needed")),0)
A14: 10 | B14: Finding jobs | C14: Collect jobs from LinkedIn, Indeed, Dice and Monster | D14: Jobs from the big job boards appear in the app. | E14: Label each job with its job board | F14: Connect to a licensed job-data provider (copying sites directly breaks their rules) | G14: Phase 1: Accounts and job matching | H14: 2 | I14: =Settings!$B$5+(H14-1)*7+4 | J14: Developer B | K14: Developer A | L14: Yes | M14: Nothing built yet | N14: Job-data provider account | O14: Not started | P14: Not started | Q14: =IF(AND(O14="Not needed",P14="Not needed"),"Not needed",IF(OR(O14="Stuck",P14="Stuck"),"Stuck",IF(AND(OR(O14="Done",O14="Not needed"),OR(P14="Done",P14="Not needed")),"Done",IF(AND(OR(O14="Not started",O14="Not needed"),OR(P14="Not started",P14="Not needed")),"Not started",IF(AND(OR(O14="Being checked",O14="Done",O14="Not needed"),OR(P14="Being checked",P14="Done",P14="Not needed")),"Being checked","In progress"))))) | R14: =IFERROR((IF(OR(O14="Not needed",O14="Stuck"),0,INDEX(Settings!$E$5:$E$8,MATCH(O14,Settings!$D$5:$D$8,0)))+IF(OR(P14="Not needed",P14="Stuck"),0,INDEX(Settings!$E$5:$E$8,MATCH(P14,Settings!$D$5:$D$8,0))))/((O14<>"Not needed")+(P14<>"Not needed")),0)
A15: 11 | B15: Finding jobs | C15: Add a job by pasting it in | D15: Users can paste any job description they found themselves. | E15: Paste-a-job box | F15: Save the pasted job and analyse it | G15: Phase 1: Accounts and job matching | H15: 2 | I15: =Settings!$B$5+(H15-1)*7+4 | J15: Developer B | K15: Developer A | L15: Yes | M15: Paste box exists, basic keyword reading | N15: — | O15: Not started | P15: Not started | Q15: =IF(AND(O15="Not needed",P15="Not needed"),"Not needed",IF(OR(O15="Stuck",P15="Stuck"),"Stuck",IF(AND(OR(O15="Done",O15="Not needed"),OR(P15="Done",P15="Not needed")),"Done",IF(AND(OR(O15="Not started",O15="Not needed"),OR(P15="Not started",P15="Not needed")),"Not started",IF(AND(OR(O15="Being checked",O15="Done",O15="Not needed"),OR(P15="Being checked",P15="Done",P15="Not needed")),"Being checked","In progress"))))) | R15: =IFERROR((IF(OR(O15="Not needed",O15="Stuck"),0,INDEX(Settings!$E$5:$E$8,MATCH(O15,Settings!$D$5:$D$8,0)))+IF(OR(P15="Not needed",P15="Stuck"),0,INDEX(Settings!$E$5:$E$8,MATCH(P15,Settings!$D$5:$D$8,0))))/((O15<>"Not needed")+(P15<>"Not needed")),0)
A16: 12 | B16: Finding jobs | C16: Remove duplicate and old jobs | D16: The same job never shows twice, and old jobs are marked. | E16: Show 'posted N days ago' | F16: Spot duplicates across sources, mark old jobs | G16: Phase 1: Accounts and job matching | H16: 2 | I16: =Settings!$B$5+(H16-1)*7+4 | J16: Developer B | K16: Developer A | L16: Yes | M16: Nothing built yet | N16: — | O16: Not started | P16: Not started | Q16: =IF(AND(O16="Not needed",P16="Not needed"),"Not needed",IF(OR(O16="Stuck",P16="Stuck"),"Stuck",IF(AND(OR(O16="Done",O16="Not needed"),OR(P16="Done",P16="Not needed")),"Done",IF(AND(OR(O16="Not started",O16="Not needed"),OR(P16="Not started",P16="Not needed")),"Not started",IF(AND(OR(O16="Being checked",O16="Done",O16="Not needed"),OR(P16="Being checked",P16="Done",P16="Not needed")),"Being checked","In progress"))))) | R16: =IFERROR((IF(OR(O16="Not needed",O16="Stuck"),0,INDEX(Settings!$E$5:$E$8,MATCH(O16,Settings!$D$5:$D$8,0)))+IF(OR(P16="Not needed",P16="Stuck"),0,INDEX(Settings!$E$5:$E$8,MATCH(P16,Settings!$D$5:$D$8,0))))/((O16<>"Not needed")+(P16<>"Not needed")),0)
... A120: 116 | B120: Launch checks | C120: Pilot test and go live | D120: Pilot users try everything, problems are fixed, then launch. | E120: Fix screen problems | F120: Fix backend problems | G120: Phase 5: Launch checks | H120: 13 | I120: =Settings!$B$5+(H120-1)*7+4 | J120: Developer B | K120: Developer A | L120: Yes | M120: Nothing built yet | N120: Pilot users | O120: Not started | P120: Not started | Q120: =IF(AND(O120="Not needed",P120="Not needed"),"Not needed",IF(OR(O120="Stuck",P120="Stuck"),"Stuck",IF(AND(OR(O120="Done",O120="Not needed"),OR(P120="Done",P120="Not needed")),"Done",IF(AND(OR(O120="Not started",O120="Not needed"),OR(P120="Not started",P120="Not needed")),"Not started",IF(AND(OR(O120="Being checked",O120="Done",O120="Not needed"),OR(P120="Being checked",P120="Done",P120="Not needed")),"Being checked","In progress"))))) | R120: =IFERROR((IF(OR(O120="Not needed",O120="Stuck"),0,INDEX(Settings!$E$5:$E$8,MATCH(O120,Settings!$D$5:$D$8,0)))+IF(OR(P120="Not needed",P120="Stuck"),0,INDEX(Settings!$E$5:$E$8,MATCH(P120,Settings!$D$5:$D$8,0))))/((O120<>"Not needed")+(P120<>"Not needed")),0)

Sheet Weekly Plan
A1: Weekly plan: 2 developers, 13 weeks
A2: What each developer delivers each week. Developer A builds the engines behind the screens; Developer B builds the screens and the platform. Every Friday: join the work up and show the client.
A4: Week | B4: Starts | C4: Phase | D4: Developer A delivers (engines) | E4: Developer B delivers (screens and platform) | F4: Checkpoint / milestone | G4: Status | H4: Features due | I4: Features done | J4: Notes
A5: 1 | B5: =Settings!$B$5+(A5-1)*7 | C5: Phase 1: Accounts and job matching | D5: Read skills, certifications, experience and keywords from job descriptions; testing kit to measure accuracy | E5: Database; secure sign-up and login for all account types; permission screen; put the app online | F5: — | G5: Not started | H5: =COUNTIF(Features!$H$5:$H$120,A5) | I5: =COUNTIFS(Features!$H$5:$H$120,A5,Features!$Q$5:$Q$120,"Done")
A6: 2 | B6: =Settings!$B$5+(A6-1)*7 | C6: Phase 1: Accounts and job matching | D6: Collect jobs (company sites, job-board feed, pasted jobs); remove duplicates; read uploaded resumes | E6: Profile page; resume and photo upload; jobs page with search, filters, save and alerts | F6: — | G6: Not started | H6: =COUNTIF(Features!$H$5:$H$120,A6) | I6: =COUNTIFS(Features!$H$5:$H$120,A6,Features!$Q$5:$Q$120,"Done")
A7: 3 | B7: =Settings!$B$5+(A7-1)*7 | C7: Phase 1: Accounts and job matching | D7: Match score, readiness and ranking for every job, with reasons; skills in demand | E7: Home dashboard on real numbers; top matches; alert notifications; welcome steps | F7: Checkpoint 1 | G7: Not started | H7: =COUNTIF(Features!$H$5:$H$120,A7) | I7: =COUNTIFS(Features!$H$5:$H$120,A7,Features!$Q$5:$Q$120,"Done")
A8: 4 | B8: =Settings!$B$5+(A8-1)*7 | C8: Phase 2: Resumes, learning and own voice | D8: Learn each user's writing voice (4 profiles); find missing skills, experience and certifications | E8: Writing-sample upload with permission; profile review page; gaps page | F8: — | G8: Not started | H8: =COUNTIF(Features!$H$5:$H$120,A8) | I8: =COUNTIFS(Features!$H$5:$H$120,A8,Features!$Q$5:$Q$120,"Done")
A9: 5 | B9: =Settings!$B$5+(A9-1)*7 | C9: Phase 2: Resumes, learning and own voice | D9: Write three resume types in the user's voice; tailor to a job; resume score | E9: Resume studio: create, compare, keep versions, download Word or PDF | F9: — | G9: Not started | H9: =COUNTIF(Features!$H$5:$H$120,A9) | I9: =COUNTIFS(Features!$H$5:$H$120,A9,Features!$Q$5:$Q$120,"Done")
A10: 6 | B10: =Settings!$B$5+(A10-1)*7 | C10: Phase 2: Resumes, learning and own voice | D10: Learning plans, roadmap, courses, certification plan; overall readiness; catch AI-sounding text | E10: Learning page with progress and streaks; readiness ring; download or delete writing samples | F10: Checkpoint 2 | G10: Not started | H10: =COUNTIF(Features!$H$5:$H$120,A10) | I10: =COUNTIFS(Features!$H$5:$H$120,A10,Features!$Q$5:$Q$120,"Done")
A11: 7 | B11: =Settings!$B$5+(A11-1)*7 | C11: Phase 3: Interview practice and LinkedIn | D11: Interview practice engine: 6 scenario types, follow-up questions, 12 starter scenarios | E11: Practice screen: type or speak answers, timer, save sessions | F11: — | G11: Not started | H11: =COUNTIF(Features!$H$5:$H$120,A11) | I11: =COUNTIFS(Features!$H$5:$H$120,A11,Features!$Q$5:$Q$120,"Done")
A12: 8 | B12: =Settings!$B$5+(A12-1)*7 | C12: Phase 3: Interview practice and LinkedIn | D12: Scores for technical depth, communication, leadership and decisions; feedback and model answers | E12: Results page; improvement over time | F12: — | G12: Not started | H12: =COUNTIF(Features!$H$5:$H$120,A12) | I12: =COUNTIFS(Features!$H$5:$H$120,A12,Features!$Q$5:$Q$120,"Done")
A13: 9 | B13: =Settings!$B$5+(A13-1)*7 | C13: Phase 3: Interview practice and LinkedIn | D13: LinkedIn posts and articles in the user's voice; content plan; outreach messages | E13: Content calendar; outreach campaigns, follow-up reminders, replies | F13: Checkpoint 3 | G13: Not started | H13: =COUNTIF(Features!$H$5:$H$120,A13) | I13: =COUNTIFS(Features!$H$5:$H$120,A13,Features!$Q$5:$Q$120,"Done")
A14: 10 | B14: =Settings!$B$5+(A14-1)*7 | C14: Phase 4: Progress tracking and organisations | D14: Progress, interview and success-rate figures; technology trends, next roles, certification advice, salaries | E14: Progress dashboard; application board; trends page | F14: — | G14: Not started | H14: =COUNTIF(Features!$H$5:$H$120,A14) | I14: =COUNTIFS(Features!$H$5:$H$120,A14,Features!$Q$5:$Q$120,"Done")
A15: 11 | B15: =Settings!$B$5+(A15-1)*7 | C15: Phase 4: Progress tracking and organisations | D15: Keep each organisation's data separate; staffing firm matching; group figures | E15: Admin pages (people, groups, spreadsheet upload); group dashboard | F15: — | G15: Not started | H15: =COUNTIF(Features!$H$5:$H$120,A15) | I15: =COUNTIFS(Features!$H$5:$H$120,A15,Features!$Q$5:$Q$120,"Done")
A16: 12 | B16: =Settings!$B$5+(A16-1)*7 | C16: Phase 4: Progress tracking and organisations | D16: Connection points for other company systems | E16: Payments for programs and licences; coaching booking; admin vs member access | F16: Checkpoint 4 | G16: Not started | H16: =COUNTIF(Features!$H$5:$H$120,A16) | I16: =COUNTIFS(Features!$H$5:$H$120,A16,Features!$Q$5:$Q$120,"Done")
A17: 13 | B17: =Settings!$B$5+(A17-1)*7 | C17: Phase 5: Launch checks | D17: Re-test accuracy; check AI cost per user | E17: Security fixes; download/delete all data; speed test with 100 users; backups | F17: Launch (8 Jan 2027 if the team takes the year-end break) | G17: Not started | H17: =COUNTIF(Features!$H$5:$H$120,A17) | I17: =COUNTIFS(Features!$H$5:$H$120,A17,Features!$Q$5:$Q$120,"Done")

Sheet Checkpoints
A1: Checkpoints: what must be true before moving to the next phase
A2: Type the measured number in the yellow 'Result we got' column. 'Passed?' fills itself in. Targets (blue) are from the 13-week plan.
A4: Checkpoint | B4: Week | C4: Date | D4: What we measure | E4: Target | F4: Need | G4: Result we got | H4: Passed? | I4: Who measures it
A5: Checkpoint 1 | B5: 3 | C5: =Settings!$B$5+(B5-1)*7+4 | D5: Share of required skills the app finds in job descriptions (vs experts) | E5: 0.9 | F5: at least | H5: =IF(G5="","Not measured",IF(IF(F5="at least",G5>=E5,G5<=E5),"Passed","Not yet")) | I5: Developer A + experts
A6: Checkpoint 1 | B6: 3 | C6: =Settings!$B$5+(B6-1)*7+4 | D6: Share of test candidates where experts agree with the top 3 jobs | E6: 0.8 | F6: at least | H6: =IF(G6="","Not measured",IF(IF(F6="at least",G6>=E6,G6<=E6),"Passed","Not yet")) | I6: Client experts
A7: Checkpoint 1 | B7: 3 | C7: =Settings!$B$5+(B7-1)*7+4 | D7: Pilot users signed up | E7: 10 | F7: at least | H7: =IF(G7="","Not measured",IF(IF(F7="at least",G7>=E7,G7<=E7),"Passed","Not yet")) | I7: Project lead
A8: Checkpoint 2 | B8: 6 | C8: =Settings!$B$5+(B8-1)*7+4 | D8: Share of generated resumes that pass the screening-software check | E8: 0.9 | F8: at least | H8: =IF(G8="","Not measured",IF(IF(F8="at least",G8>=E8,G8<=E8),"Passed","Not yet")) | I8: Developer A
A9: Checkpoint 2 | B9: 6 | C9: =Settings!$B$5+(B9-1)*7+4 | D9: Share of pilot users who prefer the own-voice resume (blind test) | E9: 0.7 | F9: at least | H9: =IF(G9="","Not measured",IF(IF(F9="at least",G9>=E9,G9<=E9),"Passed","Not yet")) | I9: Pilot users
A10: Checkpoint 3 | B10: 9 | C10: =Settings!$B$5+(B10-1)*7+4 | D10: Interview scenarios approved by client experts | E10: 12 | F10: at least | H10: =IF(G10="","Not measured",IF(IF(F10="at least",G10>=E10,G10<=E10),"Passed","Not yet")) | I10: Client experts
A11: Checkpoint 3 | B11: 9 | C11: =Settings!$B$5+(B11-1)*7+4 | D11: Share of answers where the app's score is within 1 point of the expert's | E11: 0.8 | F11: at least | H11: =IF(G11="","Not measured",IF(IF(F11="at least",G11>=E11,G11<=E11),"Passed","Not yet")) | I11: Developer A + experts
A12: Checkpoint 4 | B12: 12 | C12: =Settings!$B$5+(B12-1)*7+4 | D12: Organisations live with a group of users | E12: 1 | F12: at least | H12: =IF(G12="","Not measured",IF(IF(F12="at least",G12>=E12,G12<=E12),"Passed","Not yet")) | I12: Developer B
A13: Checkpoint 4 | B13: 12 | C13: =Settings!$B$5+(B13-1)*7+4 | D13: Times one organisation could see another's data in tests | E13: 0 | F13: at most | H13: =IF(G13="","Not measured",IF(IF(F13="at least",G13>=E13,G13<=E13),"Passed","Not yet")) | I13: Developer A
A14: Launch | B14: 13 | C14: =Settings!$B$5+(B14-1)*7+4 | D14: Serious security problems still open | E14: 0 | F14: at most | H14: =IF(G14="","Not measured",IF(IF(F14="at least",G14>=E14,G14<=E14),"Passed","Not yet")) | I14: Security reviewer
A15: Launch | B15: 13 | C15: =Settings!$B$5+(B15-1)*7+4 | D15: People using the app at once without slowdown | E15: 100 | F15: at least | H15: =IF(G15="","Not measured",IF(IF(F15="at least",G15>=E15,G15<=E15),"Passed","Not yet")) | I15: Developer B
A17: Percentages: type 0.85 for 85%.

Sheet Glossary
A1: Glossary
A2: Plain meanings for the few technical words used in this workbook.
A4: Term | B4: What it means
A5: Screen work (frontend) | B5: Everything the user sees and clicks: pages, buttons, forms, charts.
A6: Backend work | B6: The work behind the screens: saving data, AI, calculations, connecting to other services.
A7: Developer A | B7: Builds the engines behind the screens: job collection, matching, AI writing, scoring, analytics.
A8: Developer B | B8: Builds the screens and the platform: pages, logins, database, payments, admin, hosting.
A9: ATS (applicant tracking system) | B9: Software employers use to filter resumes automatically before a person reads them.
A10: Job description | B10: The text of a job advert: duties, required skills, experience.
A11: FORGE Match | B11: FORGE AI's scoring that gives each job a match percentage for a candidate. Already built for the recruiter tool.
A12: Voice profile | B12: What the app learns about how a person writes, so generated text sounds like them, not like generic AI.
A13: Checkpoint | B13: A measured test at the end of each phase. The next phase starts only when it passes.
A14: Pilot users | B14: Real early users who try the app and give feedback before launch.
A15: Licensed job-data provider | B15: A paid service that legally supplies job listings from boards like LinkedIn and Indeed.
... A18: % done | B18: Worked out from the two statuses: In progress counts as 50%, Being checked 90%, Done 100%.

Sheet Settings
A1: Settings
A2: Options used by the dropdowns and dates on the other sheets. Change the start date here and every due date moves.
A4: Setting | B4: Value | D4: Status | E4: Counts as finished | G4: Who | H4: Must have? | I4: Phase
A5: Project start date (Monday of week 1) | B5: 46300 | D5: Not started | E5: 0 | G5: Developer A | H5: Yes | I5: Phase 1: Accounts and job matching
D6: In progress | E6: 0.5 | G6: Developer B | H6: No | I6: Phase 2: Resumes, learning and own voice
D7: Being checked | E7: 0.9 | G7: Both | I7: Phase 3: Interview practice and LinkedIn
D8: Done | E8: 1 | I8: Phase 4: Progress tracking and organisations
D9: Stuck | E9: 0 | I9: Phase 5: Launch checks
D10: Not needed
D12: 'Not needed' means the feature has no screen work (or no backend work), so it is left out of the % done.
